Workbook
Name Срез_Площадка: #N/A
Name Срез_Площадка1: #N/A

Sheet Svodka (Özet Tablo)
F1: URC | M1: URC Kiralik
B2: Код Гаража | C2: Тип Т.С. | E2: Garaj Kodu | F2: EKİPMAN KOD TANIMLARI | G2: Ofis | H2: DCU | I2: SRU | J2: GARAJ-AMBAR | K2: Toplam | M2: EKİPMAN KOD TANIMLARI | N2: Ofis | O2: DCU | P2: SRU | Q2: GARAJ-AMBAR | R2: Toplam
B3: BA | C3: Легковой Автомобиль | E3: BA | F3: Binek Araç | G3: =COUNTIFS('Ekipman Listesi'!C:C,"Ofis",'Ekipman Listesi'!D:D,F3) -> 11 | H3: =COUNTIFS('Ekipman Listesi'!C:C,'Svodka (Özet Tablo)'!H$2,'Ekipman Listesi'!D:D,F3) -> 0 | I3: =COUNTIFS('Ekipman Listesi'!C:C,'Svodka (Özet Tablo)'!I$2,'Ekipman Listesi'!D:D,F3) -> 0 | J3: =COUNTIFS('Ekipman Listesi'!C:C,'Svodka (Özet Tablo)'!J$2,'Ekipman Listesi'!D:D,F3) -> 0 | K3: =SUM(G3:J3) -> 11 | M3: Binek Araç | N3: =COUNTIFS('Kiralık Ekipman Listesi'!E:E,M3,'Kiralık Ekipman Listesi'!C:C,"Ofis") -> 14 | O3: =COUNTIFS('Kiralık Ekipman Listesi'!E:E,M3,'Kiralık Ekipman Listesi'!C:C,"DCU") -> 0 | P3: =COUNTIFS('Kiralık Ekipman Listesi'!E:E,M3,'Kiralık Ekipman Listesi'!C:C,"SRU") -> 0 | Q3: =COUNTIFS('Kiralık Ekipman Listesi'!E:E,M3,'Kiralık Ekipman Listesi'!C:C,"GARAJ-AMBAR") -> 0 | R3: =SUM(N3:Q3) -> 14
B4: BUS | C4: Автобус | E4: BUS | F4: Otobüs | G4: =COUNTIFS('Ekipman Listesi'!C:C,"Ofis",'Ekipman Listesi'!D:D,F4) -> 7 | H4: =COUNTIFS('Ekipman Listesi'!C:C,'Svodka (Özet Tablo)'!H$2,'Ekipman Listesi'!D:D,F4) -> 0 | I4: =COUNTIFS('Ekipman Listesi'!C:C,'Svodka (Özet Tablo)'!I$2,'Ekipman Listesi'!D:D,F4) -> 0 | J4: =COUNTIFS('Ekipman Listesi'!C:C,'Svodka (Özet Tablo)'!J$2,'Ekipman Listesi'!D:D,F4) -> 0 | K4: =SUM(G4:J4) -> 7 | M4: Otobüs | N4: =COUNTIFS('Kiralık Ekipman Listesi'!E:E,M4,'Kiralık Ekipman Listesi'!C:C,"Ofis") -> 3 | O4: =COUNTIFS('Kiralık Ekipman Listesi'!E:E,M4,'Kiralık Ekipman Listesi'!C:C,"DCU") -> 0 | P4: =COUNTIFS('Kiralık Ekipman Listesi'!E:E,M4,'Kiralık Ekipman Listesi'!C:C,"SRU") -> 0 | Q4: =COUNTIFS('Kiralık Ekipman Listesi'!E:E,M4,'Kiralık Ekipman Listesi'!C:C,"GARAJ-AMBAR") -> 0 | R4: =SUM(N4:Q4) -> 3
B5: MB | C5: Микроавтобус | E5: MB | F5: Minibüs | G5: =COUNTIFS('Ekipman Listesi'!C:C,"Ofis",'Ekipman Listesi'!D:D,F5) -> 6 | H5: =COUNTIFS('Ekipman Listesi'!C:C,'Svodka (Özet Tablo)'!H$2,'Ekipman Listesi'!D:D,F5) -> 0 | I5: =COUNTIFS('Ekipman Listesi'!C:C,'Svodka (Özet Tablo)'!I$2,'Ekipman Listesi'!D:D,F5) -> 0 | J5: =COUNTIFS('Ekipman Listesi'!C:C,'Svodka (Özet Tablo)'!J$2,'Ekipman Listesi'!D:D,F5) -> 0 | K5: =SUM(G5:J5) -> 6 | M5: Minibüs | N5: =COUNTIFS('Kiralık Ekipman Listesi'!E:E,M5,'Kiralık Ekipman Listesi'!C:C,"Ofis") -> 12 | O5: =COUNTIFS('Kiralık Ekipman Listesi'!E:E,M5,'Kiralık Ekipman Listesi'!C:C,"DCU") -> 0 | P5: =COUNTIFS('Kiralık Ekipman Listesi'!E:E,M5,'Kiralık Ekipman Listesi'!C:C,"SRU") -> 0 | Q5: =COUNTIFS('Kiralık Ekipman Listesi'!E:E,M5,'Kiralık Ekipman Listesi'!C:C,"GARAJ-AMBAR") -> 0 | R5: =SUM(N5:Q5) -> 12
B6: MB | C6: Мини грузовик | E6: MB | F6: Kamyonet | G6: =COUNTIFS('Ekipman Listesi'!C:C,"Ofis",'Ekipman Listesi'!D:D,F6) -> 2 | H6: =COUNTIFS('Ekipman Listesi'!C:C,'Svodka (Özet Tablo)'!H$2,'Ekipman Listesi'!D:D,F6) -> 0 | I6: =COUNTIFS('Ekipman Listesi'!C:C,'Svodka (Özet Tablo)'!I$2,'Ekipman Listesi'!D:D,F6) -> 0 | J6: =COUNTIFS('Ekipman Listesi'!C:C,'Svodka (Özet Tablo)'!J$2,'Ekipman Listesi'!D:D,F6) -> 0 | K6: =SUM(G6:J6) -> 2 | M6: Kamyonet | N6: =COUNTIFS('Kiralık Ekipman Listesi'!E:E,M6,'Kiralık Ekipman Listesi'!C:C,"Ofis") -> 0 | O6: =COUNTIFS('Kiralık Ekipman Listesi'!E:E,M6,'Kiralık Ekipman Listesi'!C:C,"DCU") -> 0 | P6: =COUNTIFS('Kiralık Ekipman Listesi'!E:E,M6,'Kiralık Ekipman Listesi'!C:C,"SRU") -> 0 | Q6: =COUNTIFS('Kiralık Ekipman Listesi'!E:E,M6,'Kiralık Ekipman Listesi'!C:C,"GARAJ-AMBAR") -> 0 | R6: =SUM(N6:Q6) -> 0
B7: BL | C7: Экскаватор-Погрузчик | E7: BL | F7: Backhoe-Loader | G7: =COUNTIFS('Ekipman Listesi'!C:C,"Ofis",'Ekipman Listesi'!D:D,F7) -> 0 | H7: =COUNTIFS('Ekipman Listesi'!C:C,'Svodka (Özet Tablo)'!H$2,'Ekipman Listesi'!D:D,F7) -> 1 | I7: =COUNTIFS('Ekipman Listesi'!C:C,'Svodka (Özet Tablo)'!I$2,'Ekipman Listesi'!D:D,F7) -> 1 | J7: =COUNTIFS('Ekipman Listesi'!C:C,'Svodka (Özet Tablo)'!J$2,'Ekipman Listesi'!D:D,F7) -> 0 | K7: =SUM(G7:J7) -> 2 | M7: Backhoe-Loader | N7: =COUNTIFS('Kiralık Ekipman Listesi'!E:E,M7,'Kiralık Ekipman Listesi'!C:C,"Ofis") -> 0 | O7: =COUNTIFS('Kiralık Ekipman Listesi'!E:E,M7,'Kiralık Ekipman Listesi'!C:C,"DCU") -> 1 | P7: =COUNTIFS('Kiralık Ekipman Listesi'!E:E,M7,'Kiralık Ekipman Listesi'!C:C,"SRU") -> 0 | Q7: =COUNTIFS('Kiralık Ekipman Listesi'!E:E,M7,'Kiralık Ekipman Listesi'!C:C,"GARAJ-AMBAR") -> 0 | R7: =SUM(N7:Q7) -> 1
B8: VH | C8: Манипулятор | E8: VH | F8: Hi-up | G8: =COUNTIFS('Ekipman Listesi'!C:C,"Ofis",'Ekipman Listesi'!D:D,F8) -> 0 | H8: =COUNTIFS('Ekipman Listesi'!C:C,'Svodka (Özet Tablo)'!H$2,'Ekipman Listesi'!D:D,F8) -> 1 | I8: =COUNTIFS('Ekipman Listesi'!C:C,'Svodka (Özet Tablo)'!I$2,'Ekipman Listesi'!D:D,F8) -> 1 | J8: =COUNTIFS('Ekipman Listesi'!C:C,'Svodka (Özet Tablo)'!J$2,'Ekipman Listesi'!D:D,F8) -> 0 | K8: =SUM(G8:J8) -> 2 | M8: Hi-up | N8: =COUNTIFS('Kiralık Ekipman Listesi'!E:E,M8,'Kiralık Ekipman Listesi'!C:C,"Ofis") -> 0 | O8: =COUNTIFS('Kiralık Ekipman Listesi'!E:E,M8,'Kiralık Ekipman Listesi'!C:C,"DCU") -> 1 | P8: =COUNTIFS('Kiralık Ekipman Listesi'!E:E,M8,'Kiralık Ekipman Listesi'!C:C,"SRU") -> 0 | Q8: =COUNTIFS('Kiralık Ekipman Listesi'!E:E,M8,'Kiralık Ekipman Listesi'!C:C,"GARAJ-AMBAR") -> 0 | R8: =SUM(N8:Q8) -> 1
B9: VM | C9: Мобильный кран | E9: VM | F9: Mobil Vinç | G9: =COUNTIFS('Ekipman Listesi'!C:C,"Ofis",'Ekipman Listesi'!D:D,F9) -> 0 | H9: =COUNTIFS('Ekipman Listesi'!C:C,'Svodka (Özet Tablo)'!H$2,'Ekipman Listesi'!D:D,F9) -> 0 | I9: =COUNTIFS('Ekipman Listesi'!C:C,'Svodka (Özet Tablo)'!I$2,'Ekipman Listesi'!D:D,F9) -> 3 | J9: =COUNTIFS('Ekipman Listesi'!C:C,'Svodka (Özet Tablo)'!J$2,'Ekipman Listesi'!D:D,F9) -> 0 | K9: =SUM(G9:J9) -> 3 | M9: Mobil Vinç | N9: =COUNTIFS('Kiralık Ekipman Listesi'!E:E,M9,'Kiralık Ekipman Listesi'!C:C,"Ofis") -> 0 | O9: =COUNTIFS('Kiralık Ekipman Listesi'!E:E,M9,'Kiralık Ekipman Listesi'!C:C,"DCU") -> 12 | P9: =COUNTIFS('Kiralık Ekipman Listesi'!E:E,M9,'Kiralık Ekipman Listesi'!C:C,"SRU") -> 2 | Q9: =COUNTIFS('Kiralık Ekipman Listesi'!E:E,M9,'Kiralık Ekipman Listesi'!C:C,"GARAJ-AMBAR") -> 1 | R9: =SUM(N9:Q9) -> 15
B10: TR | C10: Седельный Тягач | E10: TR | F10: Tır (Çekici) | G10: =COUNTIFS('Ekipman Listesi'!C:C,"Ofis",'Ekipman Listesi'!D:D,F10) -> 0 | H10: =COUNTIFS('Ekipman Listesi'!C:C,'Svodka (Özet Tablo)'!H$2,'Ekipman Listesi'!D:D,F10) -> 2 | I10: =COUNTIFS('Ekipman Listesi'!C:C,'Svodka (Özet Tablo)'!I$2,'Ekipman Listesi'!D:D,F10) -> 2 | J10: =COUNTIFS('Ekipman Listesi'!C:C,'Svodka (Özet Tablo)'!J$2,'Ekipman Listesi'!D:D,F10) -> 0 | K10: =SUM(G10:J10) -> 4 | M10: Tır (Çekici) | N10: =COUNTIFS('Kiralık Ekipman Listesi'!E:E,M10,'Kiralık Ekipman Listesi'!C:C,"Ofis") -> 0 | O10: =COUNTIFS('Kiralık Ekipman Listesi'!E:E,M10,'Kiralık Ekipman Listesi'!C:C,"DCU") -> 5 | P10: =COUNTIFS('Kiralık Ekipman Listesi'!E:E,M10,'Kiralık Ekipman Listesi'!C:C,"SRU") -> 1 | Q10: =COUNTIFS('Kiralık Ekipman Listesi'!E:E,M10,'Kiralık Ekipman Listesi'!C:C,"GARAJ-AMBAR") -> 0 | R10: =SUM(N10:Q10) -> 6
B11: EBP | C11: Подъемник Коленчатый | E11: EBP | F11: Eklemli Bomlu Platform (Manlift) | G11: =COUNTIFS('Ekipman Listesi'!C:C,"Ofis",'Ekipman Listesi'!D:D,F11) -> 0 | H11: =COUNTIFS('Ekipman Listesi'!C:C,'Svodka (Özet Tablo)'!H$2,'Ekipman Listesi'!D:D,F11) -> 6 | I11: =COUNTIFS('Ekipman Listesi'!C:C,'Svodka (Özet Tablo)'!I$2,'Ekipman Listesi'!D:D,F11) -> 5 | J11: =COUNTIFS('Ekipman Listesi'!C:C,'Svodka (Özet Tablo)'!J$2,'Ekipman Listesi'!D:D,F11) -> 0 | K11: =SUM(G11:J11) -> 11 | M11: Eklemli Bomlu Platform (Manlift) | N11: =COUNTIFS('Kiralık Ekipman Listesi'!E:E,M11,'Kiralık Ekipman Listesi'!C:C,"Ofis") -> 0 | O11: =COUNTIFS('Kiralık Ekipman Listesi'!E:E,M11,'Kiralık Ekipman Listesi'!C:C,"DCU") -> 19 | P11: =COUNTIFS('Kiralık Ekipman Listesi'!E:E,M11,'Kiralık Ekipman Listesi'!C:C,"SRU") -> 1 | Q11: =COUNTIFS('Kiralık Ekipman Listesi'!E:E,M11,'Kiralık Ekipman Listesi'!C:C,"GARAJ-AMBAR") -> 0 | R11: =SUM(N11:Q11) -> 20
B12: EXL | C12: Колесный экскаватор | E12: EXL | F12: Excavatör (Lastikli) | G12: =COUNTIFS('Ekipman Listesi'!C:C,"Ofis",'Ekipman Listesi'!D:D,F12) -> 0 | H12: =COUNTIFS('Ekipman Listesi'!C:C,'Svodka (Özet Tablo)'!H$2,'Ekipman Listesi'!D:D,F12) -> 0 | I12: =COUNTIFS('Ekipman Listesi'!C:C,'Svodka (Özet Tablo)'!I$2,'Ekipman Listesi'!D:D,F12) -> 1 | J12: =COUNTIFS('Ekipman Listesi'!C:C,'Svodka (Özet Tablo)'!J$2,'Ekipman Listesi'!D:D,F12) -> 0 | K12: =SUM(G12:J12) -> 1 | M12: Excavatör (Lastikli) | N12: =COUNTIFS('Kiralık Ekipman Listesi'!E:E,M12,'Kiralık Ekipman Listesi'!C:C,"Ofis") -> 0 | O12: =COUNTIFS('Kiralık Ekipman Listesi'!E:E,M12,'Kiralık Ekipman Listesi'!C:C,"DCU") -> 0 | P12: =COUNTIFS('Kiralık Ekipman Listesi'!E:E,M12,'Kiralık Ekipman Listesi'!C:C,"SRU") -> 0 | Q12: =COUNTIFS('Kiralık Ekipman Listesi'!E:E,M12,'Kiralık Ekipman Listesi'!C:C,"GARAJ-AMBAR") -> 0 | R12: =SUM(N12:Q12) -> 0
B13: FL | C13: Телескопический Погрузчик | E13: FL | F13: Forklift (Teleskopik) | G13: =COUNTIFS('Ekipman Listesi'!C:C,"Ofis",'Ekipman Listesi'!D:D,F13) -> 0 | H13: =COUNTIFS('Ekipman Listesi'!C:C,'Svodka (Özet Tablo)'!H$2,'Ekipman Listesi'!D:D,F13) -> 1 | I13: =COUNTIFS('Ekipman Listesi'!C:C,'Svodka (Özet Tablo)'!I$2,'Ekipman Listesi'!D:D,F13) -> 1 | J13: =COUNTIFS('Ekipman Listesi'!C:C,'Svodka (Özet Tablo)'!J$2,'Ekipman Listesi'!D:D,F13) -> 0 | K13: =SUM(G13:J13) -> 2 | M13: Forklift (Teleskopik) | N13: =COUNTIFS('Kiralık Ekipman Listesi'!E:E,M13,'Kiralık Ekipman Listesi'!C:C,"Ofis") -> 0 | O13: =COUNTIFS('Kiralık Ekipman Listesi'!E:E,M13,'Kiralık Ekipman Listesi'!C:C,"DCU") -> 0 | P13: =COUNTIFS('Kiralık Ekipman Listesi'!E:E,M13,'Kiralık Ekipman Listesi'!C:C,"SRU") -> 1 | Q13: =COUNTIFS('Kiralık Ekipman Listesi'!E:E,M13,'Kiralık Ekipman Listesi'!C:C,"GARAJ-AMBAR") -> 0 | R13: =SUM(N13:Q13) -> 1
B14: FLM | C14: Вилочный Погрузчик | E14: FLM | F14: Forklift Mini (Çatallı Mini Forklift) | G14: =COUNTIFS('Ekipman Listesi'!C:C,"Ofis",'Ekipman Listesi'!D:D,F14) -> 0 | H14: =COUNTIFS('Ekipman Listesi'!C:C,'Svodka (Özet Tablo)'!H$2,'Ekipman Listesi'!D:D,F14) -> 1 | I14: =COUNTIFS('Ekipman Listesi'!C:C,'Svodka (Özet Tablo)'!I$2,'Ekipman Listesi'!D:D,F14) -> 0 | J14: =COUNTIFS('Ekipman Listesi'!C:C,'Svodka (Özet Tablo)'!J$2,'Ekipman Listesi'!D:D,F14) -> 1 | K14: =SUM(G14:J14) -> 2 | M14: Forklift Mini (Çatallı Mini Forklift) | N14: =COUNTIFS('Kiralık Ekipman Listesi'!E:E,M14,'Kiralık Ekipman Listesi'!C:C,"Ofis") -> 0 | O14: =COUNTIFS('Kiralık Ekipman Listesi'!E:E,M14,'Kiralık Ekipman Listesi'!C:C,"DCU") -> 0 | P14: =COUNTIFS('Kiralık Ekipman Listesi'!E:E,M14,'Kiralık Ekipman Listesi'!C:C,"SRU") -> 0 | Q14: =COUNTIFS('Kiralık Ekipman Listesi'!E:E,M14,'Kiralık Ekipman Listesi'!C:C,"GARAJ-AMBAR") -> 0 | R14: =SUM(N14:Q14) -> 0
... B22: COM | C22: Компрессор | E22: COM | F22: Kompressör | G22: =COUNTIFS('Ekipman Listesi'!C:C,"Ofis",'Ekipman Listesi'!D:D,F22) -> 0 | H22: =COUNTIFS('Ekipman Listesi'!C:C,'Svodka (Özet Tablo)'!H$2,'Ekipman Listesi'!D:D,F22) -> 11 | I22: =COUNTIFS('Ekipman Listesi'!C:C,'Svodka (Özet Tablo)'!I$2,'Ekipman Listesi'!D:D,F22) -> 6 | J22: =COUNTIFS('Ekipman Listesi'!C:C,'Svodka (Özet Tablo)'!J$2,'Ekipman Listesi'!D:D,F22) -> 0 | K22: =SUM(G22:J22) -> 17 | M22: Kompressör | N22: =COUNTIFS('Kiralık Ekipman Listesi'!E:E,M22,'Kiralık Ekipman Listesi'!C:C,"Ofis") -> 0 | O22: =COUNTIFS('Kiralık Ekipman Listesi'!E:E,M22,'Kiralık Ekipman Listesi'!C:C,"DCU") -> 0 | P22: =COUNTIFS('Kiralık Ekipman Listesi'!E:E,M22,'Kiralık Ekipman Listesi'!C:C,"SRU") -> 0 | Q22: =COUNTIFS('Kiralık Ekipman Listesi'!E:E,M22,'Kiralık Ekipman Listesi'!C:C,"GARAJ-AMBAR") -> 0 | R22: =SUM(N22:Q22) -> 0
E23: Toplam | G23: =SUM(G3:G22) -> 26 | H23: =SUM(H3:H22) -> 33 | I23: =SUM(I3:I22) -> 34 | J23: =SUM(J3:J22) -> 3 | K23: =SUM(G23:J23) -> 96 | M23: Toplam | N23: =SUM(N3:N22) -> 29 | O23: =SUM(O3:O22) -> 45 | P23: =SUM(P3:P22) -> 7 | Q23: =SUM(Q3:Q22) -> 1 | R23: =SUM(R3:R22) -> 82

Sheet Ekipman Listesi
F1: URC Moskova Makine Ekipman Parkı
A2: № | B2: ID No | C2: Şantiye | D2: Makine Ekipman Tipi TR | E2: Makine Ekipman Tipi RU | F2: Marka / Model | G2: Plaka | H2: VIN № | I2: Teknik Özellikler | J2: Üretim Yılı | K2: Ağırlık, kg | L2: Genel Boyutlar (U, G, Y) | M2: Motor Gücü (kW) | N2: Motor Marka ve Modeli | O2: Motor Numarası | P2: Kayıtlı Şirket | Q2: Geliş Tarihi | R2: Belge / Doküman | S2: Not
A3: № | B3: ID Номер | C3: Площадка | D3: Тип Транспортного Средства ТР | E3: Тип Транспортного Средства РУ | F3: Марка/Модел | G3: Гос Номер | H3: VIN № | I3: Характеристики | J3: Год Выпуска, г | K3: Вес ,Кг | L3: Габаритные Размеры (Д, Ш, В) | M3: Мощность Двигателя, кВт | N3: Марка Двигателя | O3: Номер Двигателя | P3: Зарегистрированная фирма | Q3: Дата Поступления | R3: Документы | S3: Описание
A4: =SUBTOTAL(3,B$4:B4) -> 1 | B4: BA-101 | C4: Ofis | D4: Binek Araç | E4: Легковой Автомобиль | F4: HYUNDAI SOLARIS | G4: В 417 ХТ 799 | H4: Z94K241CBMR289230 | I4: 1610 кг - 4х2 Бензин | J4: 2021 | K4: 1230 | L4: 4405х1729х1469 мм | M4: 90,2 кВт | N4: Hyundai МО tor G4FG-5 | O4: G4FGLW585945 | P4: USTAY | Q4: - | R4: Ortak Klasor Linki verilecek
A5: =SUBTOTAL(3,B$4:B5) -> 2 | B5: BA-102 | C5: Ofis | D5: Binek Araç | E5: Легковой Автомобиль | F5: HYUNDAI SOLARIS | G5: В 420 ХТ 799 | H5: Z94K241CBMR289284 | I5: 1610 кг - 4х2 Бензин | J5: 2021 | K5: 1230 | L5: 4405х1729х1469 мм | M5: 90,2 кВт | N5: Hyundai МО tor G4FG-5 | O5: G4FGLW580487 | P5: USTAY | Q5: - | R5: Ortak Klasor Linki verilecek
A6: =SUBTOTAL(3,B$4:B6) -> 3 | B6: BA-103 | C6: Ofis | D6: Binek Araç | E6: Легковой Автомобиль | F6: MITSUBISHI L200 | G6: Р 689 ТО 799 | H6: MMCJJKL10MH000643 | I6: 2850 кг - 4х4 Дизель | J6: 2020 | K6: 1915 | L6: 5225х1815х1775 мм | M6: 113 кВт | N6: Mitsubishi, 4N15 | O6: 4N15 UGX0712 | P6: USTAY | Q6: - | R6: Ortak Klasor Linki verilecek
A7: =SUBTOTAL(3,B$4:B7) -> 4 | B7: BA-104 | C7: Ofis | D7: Binek Araç | E7: Легковой Автомобиль | F7: MITSUBISHI L200 | G7: У 268 ЕУ 797 | H7: MMCJJKL10MH001839 | I7: 2850 кг - 4х4 Дизель | J7: 2021 | K7: 1915 | L7: 5225х1815х1775 мм | M7: 113 кВт | N7: Mitsubishi, 4N15 | O7: 4N15 UHG6457 | P7: USTAY | Q7: - | R7: Ortak Klasor Linki verilecek
A8: =SUBTOTAL(3,B$4:B8) -> 5 | B8: BA-105 | C8: Ofis | D8: Binek Araç | E8: Легковой Автомобиль | F8: MITSUBISHI L200 | G8: Т 543 АС 797 | H8: MMCJJKL10LH010942 | I8: 2850 кг - 4х4 Дизель | J8: 2019 | K8: 1930 | L8: 5225х1815х1775 мм | M8: 113 кВт | N8: Mitsubishi, 4N15 | O8: 4N15 UGG9810 | P8: USTAY | Q8: - | R8: Ortak Klasor Linki verilecek
A9: =SUBTOTAL(3,B$4:B9) -> 6 | B9: BA-106 | C9: Ofis | D9: Binek Araç | E9: Легковой Автомобиль | F9: TOYOTA LAND CRUISER 150 | G9: Р 101 АН 797 | H9: JTEBX3FJ50K328066 | I9: 2850 кг - 4х4 Бензин | J9: 2020 | K9: 2265 | L9: 4840х1855х1845 мм | M9: 120 кВт | N9: Toyota 2TR-FE | O9: 2TR 2211878 | P9: USTAY | Q9: - | R9: Ortak Klasor Linki verilecek
A10: =SUBTOTAL(3,B$4:B10) -> 7 | B10: BA-107 | C10: Ofis | D10: Binek Araç | E10: Легковой Автомобиль | F10: TOYOTA LAND CRUISER 150 | G10: О 707 ВН 797 | H10: JTEBX3FJ40K332898 | I10: 2850 кг - 4x4 Бензин | J10: 2020 | K10: 2265 | L10: 4840х1855х1845 мм | M10: 120 кВт | N10: Toyota 2TR-FE | O10: 2TR 2279200 | P10: USTAY | Q10: - | R10: Ortak Klasor Linki verilecek
A11: =SUBTOTAL(3,B$4:B11) -> 8 | B11: BA-108 | C11: Ofis | D11: Binek Araç | E11: Легковой Автомобиль | F11: UAZ PICKUP 23632 | G11: Х 805 АС 797 | H11: XTT236320M1005935 | I11: 2795 кг - 4х4 Бензин | J11: 2020 | K11: 2105 | L11: 5125х1915х1915 мм | M11: 110 кВт | N11: ЗМЗ-409051 | O11: XTT0409051L3023255 | P11: USTAY | Q11: - | R11: Ortak Klasor Linki verilecek
A12: =SUBTOTAL(3,B$4:B12) -> 9 | B12: BA-109 | C12: Ofis | D12: Binek Araç | E12: Легковой Автомобиль | F12: TOYOTA CAMRY | G12: В 695 ХТ 799 | H12: XW7BB4HK70S201634 | I12: 2030 кг - 4х2 Бензин | J12: 2021 | K12: 1560 | L12: 4885х1840х1455 мм | M12: 110 кВт | N12: Toyota, M20A-FKS | O12: M20A BD36554 | P12: USTAY | Q12: - | R12: Ortak Klasor Linki verilecek
A13: =SUBTOTAL(3,B$4:B13) -> 10 | B13: BA-110 | C13: Ofis | D13: Binek Araç | E13: Легковой Автомобиль | F13: LADA VESTA | G13: А 581 ХЕ 797 | H13: XTAGFK350T1012921 | I13: 1790 кг - 4х2 Бензин | J13: 2025 | K13: 1395 | L13: 4440х1764х1496 мм | M13: 75 кВт | N13: ВАЗ-21129 | O13: - | P13: URC | Q13: - | R13: Ortak Klasor Linki verilecek
A14: =SUBTOTAL(3,B$4:B14) -> 11 | B14: BA-111 | C14: Ofis | D14: Binek Araç | E14: Легковой Автомобиль | F14: LADA VESTA | G14: А 582 СХ 797 | H14: XTAGFK350T1012945 | I14: 1790 кг - 4х2 | J14: 2025 | K14: 1395 | L14: 4440х1764х1496 мм | M14: 75 кВт | N14: ВАЗ-21129 | O14: - | P14: URC | Q14: - | R14: Ortak Klasor Linki verilecek
A15: =SUBTOTAL(3,B$4:B15) -> 12 | B15: BL-101 | C15: DCU | D15: Backhoe-Loader | E15: Экскаватор-Погрузчик | F15: HIDROMEK HMK 102B | G15: 4670 ММ 77 | H15: HMK102BLK2B260171 | I15: 1,1 м³ (ковша) | J15: 2020 | K15: 9110 | L15: 6070х2420х3590 мм | M15: 74,5 кВт | N15: Perkins 1104D-44TA | O15: NM75621U330992E | P15: ООО "МИР СПЕХТЕХНИКИ" | Q15: - | R15: Ortak Klasor Linki verilecek
... A23: =SUBTOTAL(3,B$4:B23) -> 20 | B23: BUS-107 | C23: Ofis | D23: Otobüs | E23: Автобус | F23: LIAZ 529267 | G23: С 147 ХЕ 797 | H23: XTY529267L0009362 | I23: 18000 кг - 105 место (30+1) | J23: 2020 | K23: 10500 | L23: 12410х2500х3139 мм | M23: 210 кВт | N23: ЯМЗ, 53624-40 | O23: K0102649 | P23: ООО "МИР СПЕХТЕХНИКИ" | Q23: - | R23: Ortak Klasor Linki verilecek
A24: =SUBTOTAL(3,B$4:B24) -> 21 | B24: EBP-101 | C24: DCU | D24: Eklemli Bomlu Platform (Manlift) | E24: Подъемник Коленчатый | F24: ZOOMLION ZA32J | G24: 0337 МО 77 | H24: 0774100000M000004 | I24: 33,85 м 250 кг | J24: 2022 | K24: 20000 | L24: 12600х2490х3100 мм | M24: 54 кВт | N24: Cummins QSF2.8 | O24: 77084359 | P24: ООО "МИР СПЕХТЕХНИКИ" | Q24: - | R24: Ortak Klasor Linki verilecek
A25: =SUBTOTAL(3,B$4:B25) -> 22 | B25: EBP-102 | C25: SRU | D25: Eklemli Bomlu Platform (Manlift) | E25: Подъемник Коленчатый | F25: ZOOMLION ZA32J | G25: 0340 МО 77 | H25: 0774100000M000005 | I25: 33,85 м 250 кг | J25: 2022 | K25: 20000 | L25: 12600х2490х3100 мм | M25: 54 кВт | N25: Cummins QSF2.8 | O25: 77103314 | P25: ООО "МИР СПЕХТЕХНИКИ" | Q25: - | R25: Ortak Klasor Linki verilecek
A26: =SUBTOTAL(3,B$4:B26) -> 23 | B26: EBP-103 | C26: SRU | D26: Eklemli Bomlu Platform (Manlift) | E26: Подъемник Коленчатый | F26: ZOOMLION ZA32J | G26: 0339 МО 77 | H26: 0774100000M000002 | I26: 33,85 м 250 кг | J26: 2022 | K26: 20000 | L26: 12600х2490х3100 мм | M26: 54 кВт | N26: Cummins QSF2.8 | O26: 77081279 | P26: ООО "МИР СПЕХТЕХНИКИ" | Q26: - | R26: Ortak Klasor Linki verilecek
A27: =SUBTOTAL(3,B$4:B27) -> 24 | B27: EBP-104 | C27: SRU | D27: Eklemli Bomlu Platform (Manlift) | E27: Подъемник Коленчатый | F27: ZOOMLION ZA32J | G27: 0338 МО 77 | H27: 0774100000M000003 | I27: 33,85 м 250 кг | J27: 2022 | K27: 20000 | L27: 12600х2490х3100 мм | M27: 54 кВт | N27: Cummins QSF2.8 | O27: 77085005 | P27: ООО "МИР СПЕХТЕХНИКИ" | Q27: - | R27: Ortak Klasor Linki verilecek
A28: =SUBTOTAL(3,B$4:B28) -> 25 | B28: EBP-105 | C28: SRU | D28: Eklemli Bomlu Platform (Manlift) | E28: Подъемник Коленчатый | F28: ZOOMLION ZA24J | G28: 0342 МО 77 | H28: 0774000000M000042 | I28: 24,5 м 250 кг | J28: 2022 | K28: 20000 | L28: 11250х2490х3000 мм | M28: 54 кВт | N28: Cummins QSF2.8 | O28: 77103231 | P28: ООО "МИР СПЕХТЕХНИКИ" | Q28: - | R28: Ortak Klasor Linki verilecek
A29: =SUBTOTAL(3,B$4:B29) -> 26 | B29: EBP-106 | C29: SRU | D29: Eklemli Bomlu Platform (Manlift) | E29: Подъемник Коленчатый | F29: ZOOMLION ZA24J | G29: 0341 МО 77 | H29: 0774000000M000041 | I29: 24,5 м 250 кг | J29: 2022 | K29: 20000 | L29: 11250х2490х3000 мм | M29: 54 кВт | N29: Cummins QSF2.8 | O29: 77103167 | P29: ООО "МИР СПЕХТЕХНИКИ" | Q29: - | R29: Ortak Klasor Linki verilecek
A30: =SUBTOTAL(3,B$4:B30) -> 27 | B30: EBP-107 | C30: DCU | D30: Eklemli Bomlu Platform (Manlift) | E30: Подъемник Коленчатый | F30: ZOOMLION ZA14J | G30: 0343 МО 77 | H30: 0773400000M000163 | I30: 13,8 м 250 кг | J30: 2021 | K30: 7400 | L30: 6570х2300х2270 мм | M30: 36 кВт | N30: Kubota V2403 | O30: 7ML1278 | P30: ООО "МИР СПЕХТЕХНИКИ" | Q30: - | R30: Ortak Klasor Linki verilecek
A31: =SUBTOTAL(3,B$4:B31) -> 28 | B31: EBP-108 | C31: DCU | D31: Eklemli Bomlu Platform (Manlift) | E31: Подъемник Коленчатый | F31: HAULOTTE HA41RTJPRO | G31: 5952 МХ 77 | H31: 2058325 | I31: 41 м 230 кг | J31: 2019 | K31: 24130 | L31: 2500х13100х2990 мм | M31: 62,5 кВт | N31: Perkins NL75015 | O31: U317442D | P31: URC | Q31: - | R31: Ortak Klasor Linki verilecek
A32: =SUBTOTAL(3,B$4:B32) -> 29 | B32: EBP-109 | C32: DCU | D32: Eklemli Bomlu Platform (Manlift) | E32: Подъемник Коленчатый | F32: HAULOTTE HA41RTJPRO | G32: 5953 МХ 77 | H32: 2063998 | I32: 41 м 230 кг | J32: 2019 | K32: 24130 | L32: 2500х13100х2990 мм | M32: 62,5 кВт | N32: Perkins NL75015 | O32: U322174E | P32: URC | Q32: - | R32: Ortak Klasor Linki verilecek
A33: =SUBTOTAL(3,B$4:B33) -> 30 | B33: EBP-110 | C33: DCU | D33: Eklemli Bomlu Platform (Manlift) | E33: Подъемник Коленчатый | F33: HAULOTTE HA32RTJPRO | G33: 5951 МХ 77 | H33: 2055944 | I33: 31,8 м 250 кг | J33: 2019 | K33: 20350 | L33: 2530х8900х3380 мм | M33: 62,5 кВт | N33: Perkins NL75015 | O33: U314952D | P33: URC | Q33: - | R33: Ortak Klasor Linki verilecek
A34: =SUBTOTAL(3,B$4:B34) -> 31 | B34: EBP-111 | C34: DCU | D34: Eklemli Bomlu Platform (Manlift) | E34: Подъемник Коленчатый | F34: HAULOTTE HA120PX | G34: 5954 МХ 77 | H34: 2062084 | I34: 12,4 м 230 кг | J34: 2019 | K34: 5850 | L34: 5500х1900х2200 мм | M34: 21 кВт | N34: Lombardini Kohler K0W 140DE525 | O34: 4909103000 | P34: URC | Q34: - | R34: Ortak Klasor Linki verilecek
A35: =SUBTOTAL(3,B$4:B35) -> 32 | B35: EXL-101 | C35: SRU | D35: Excavatör (Lastikli) | E35: Колесный экскаватор | F35: XCMG ХЕ210WD | G35: 5950 МХ 77 | H35: XUGB210WKNKA00527 | I35: 1 м³ (ковша) | J35: 2023 | K35: 21000 | L35: 9597х2495х3170 мм | M35: 135 кВт | N35: Cummins QSB 7 | O35: 90212110 | P35: URC | Q35: - | R35: Ortak Klasor Linki verilecek
A36: =SUBTOTAL(3,B$4:B36) -> 33 | B36: FL-101 | C36: SRU | D36: Forklift (Teleskopik) | E36: Телескопический Погрузчик | F36: SANY STH1056A | G36: 4650 РМ 77 | H36: TH1056CC0578 | I36: 4,54 т - 17,1 м | J36: 2023 | K36: 19840 | L36: 6167х2560х2550 мм | M36: 93 кВт | N36: Cummins QSF3.8 | O36: 77279092 | P36: URC | Q36: - | R36: Ortak Klasor Linki verilecek
A37: =SUBTOTAL(3,B$4:B37) -> 34 | B37: FL-102 | C37: DCU | D37: Forklift (Teleskopik) | E37: Телескопический Погрузчик | F37: SANY STH1840E | G37: 4085 MX 77 | H37: TH1840CF1226 | I37: 4 т - 17,55 м | J37: 2025 | K37: 12300 | L37: 6220х2426х2595 мм | M37: 73 кВт | N37: Cummins QSF3.8 | O37: 77771712 | P37: URC | Q37: - | R37: Ortak Klasor Linki verilecek
A38: =SUBTOTAL(3,B$4:B38) -> 35 | B38: FLM-101 | C38: GARAJ-AMBAR | D38: Forklift Mini (Çatallı Mini Forklift) | E38: Вилочный Погрузчик | F38: ZAUBERG DB50-I | G38: 4082 MX 77 | H38: 010503F5781 | I38: 5 т - 3 м | J38: 2023 | K38: 8220 | L38: 480х1500х2500 мм | M38: 82,4 кВт | N38: ISUZU 6BG1 | O38: 430669 | P38: URC | Q38: - | R38: Ortak Klasor Linki verilecek
A39: =SUBTOTAL(3,B$4:B39) -> 36 | B39: FLM-102 | C39: DCU | D39: Forklift Mini (Çatallı Mini Forklift) | E39: Вилочный Погрузчик | F39: LONKING LG50DT | G39: 4083 MX 77 | H39: L97115051S3060308 | I39: 8 т - 3 м | J39: 2025 | K39: 7230 | L39: 4715х1995х2450 мм | M39: 60 кВт | N39: XICHAI, 4DX23-82GG3U | O39: WA413401 | P39: URC | Q39: - | R39: Ortak Klasor Linki verilecek
A40: =SUBTOTAL(3,B$4:B40) -> 37 | B40: MB-101 | C40: Ofis | D40: Minibüs | E40: Микроавтобус | F40: GAZELLE CITY A68R52 | G40: В 115 ХК 797 | H40: X96A68R52T0030224 | I40: 4950 кг - 22 место (17+1) | J40: 2025 | K40: 3454 | L40: 6620х2200х2720 мм | M40: 110 кВт | N40: GAZ G3A1 | O40: G3A1R035113 | P40: ООО "МИР СПЕХТЕХНИКИ" | Q40: - | R40: Ortak Klasor Linki verilecek
A41: =SUBTOTAL(3,B$4:B41) -> 38 | B41: MB-102 | C41: Ofis | D41: Minibüs | E41: Микроавтобус | F41: GAZELLE CITY A68R52 | G41: В 118 СМ 797 | H41: X96A68R52T0030209 | I41: 4950 кг - 22 место (17+1) | J41: 2025 | K41: 3454 | L41: 6620х2200х2720 мм | M41: 110 кВт | N41: GAZ G3A1 | O41: G3A1R039134 | P41: ООО "МИР СПЕХТЕХНИКИ" | Q41: - | R41: Ortak Klasor Linki verilecek
A42: =SUBTOTAL(3,B$4:B42) -> 39 | B42: MB-103 | C42: Ofis | D42: Minibüs | E42: Микроавтобус | F42: GAZ GAZELLE NEXT A65R35 | G42: Е 665 КТ 797 | H42: X96A65R35L0893558 | I42: 4200 кг - 18 место (17+1) | J42: 2020 | K42: 2980 | L42: 6415х2068х2837 мм | M42: 76,7 кВт | N42: УМЗ A2755 | O42: A27550L0100600 | P42: ООО "МИР СПЕХТЕХНИКИ" | Q42: - | R42: Ortak Klasor Linki verilecek
A43: =SUBTOTAL(3,B$4:B43) -> 40 | B43: MB-104 | C43: Ofis | D43: Minibüs | E43: Микроавтобус | F43: UAZ 374195-05 | G43: К 480 ВЕ 797 | H43: XTT374195M1207522 | I43: 2845 кг - 4х4 Бензин | J43: 2020 | K43: 1920 | L43: 4363х1940х2064 мм | M43: 82,5 кВт | N43: ЗМЗ-409110 | O43: XTT0409110L3031114 | P43: USTAY | Q43: - | R43: Ortak Klasor Linki verilecek
A44: =SUBTOTAL(3,B$4:B44) -> 41 | B44: MB-106 | C44: Ofis | D44: Minibüs | E44: Микроавтобус | F44: GAZ GAZELLE NEXT С41К92 | G44: Р 092 АН 797 | H44: X96C41R92L2785312 | I44: 4600 кг | J44: 2019 | K44: 2415 | L44: 6709х2160х2744 мм | M44: 110 кВт | N44: Cummins ISF2.8 | O44: 76591385 | P44: USTAY | Q44: - | R44: Ortak Klasor Linki verilecek
A45: =SUBTOTAL(3,B$4:B45) -> 42 | B45: MB-107 | C45: Ofis | D45: Kamyonet | E45: Мини грузовик | F45: GAZ GAZELLE NEXT A21R32 | G45: Т 457 ЕК 797 | H45: X96A21R32L2820033 | I45: 1500 кг место (3) | J45: 2020 | K45: 2310 | L45: 6709х2068х2137 мм | M45: 110 кВт | N45: Cummins ISF2.8 | O45: 76795837 | P45: USTAY | Q45: - | R45: Ortak Klasor Linki verilecek
A46: =SUBTOTAL(3,B$4:B46) -> 43 | B46: MB-108 | C46: Ofis | D46: Minibüs | E46: Микроавтобус | F46: СОБОЛЬ 2752 | G46: А 558 ТУ 797 | H46: X96275200S1023639 | I46: 800 кг место (7) | J46: 2025 | K46: 2045 | L46: 4810х2030х2385 мм | M46: 88 кВт | N46: Cummins ISF2.8 | O46: - | P46: URC | Q46: - | R46: Ortak Klasor Linki verilecek
A47: =SUBTOTAL(3,B$4:B47) -> 44 | B47: MB-109 | C47: Ofis | D47: Kamyonet | E47: Мини грузовик | F47: GAZ GAZELLE NEXT A21R32 | G47: Р 212 СР 797 | H47: X96A21R32S2949710 | I47: 1500 кг место (3) | J47: 2025 | K47: 2315 | L47: 6709х2068х2137 мм | M47: 110 кВт | N47: GAZ G3A1 | O47: G31AR053134 | P47: USTAY | Q47: - | R47: Ortak Klasor Linki verilecek
...

Sheet Kiralık Ekipman Listesi
B1: URC Moskova Kiralık Makine Ekipman Parkı
A2: № | B2: Фирма | C2: Площадка | D2: ID Номер | E2: Тип Транспортоного Средства ТР | F2: Тип Транспортоного Средства РУ | G2: Марка/Модел | H2: Гос Номер | I2: характеристики | J2: Дата Начала | K2: Описание
A3: =SUBTOTAL(3,C$3:C3) -> 1 | B3: OOO M KRAN | C3: SRU | E3: Mobil Vinç | F3: Мобильный кран | G3: LIEBHERR- LTR 1100 2.1 | H3: 4382РK77 | I3: 100 тон
A4: =SUBTOTAL(3,C$3:C4) -> 2 | B4: OOO M KRAN | C4: SRU | E4: Mobil Vinç | F4: Мобильный кран | G4: LIEBHERR-LTM 1100-4.2 | H4: С213АК799 | I4: 100 тон
A5: =SUBTOTAL(3,C$3:C5) -> 3 | B5: OOO M KRAN | C5: SRU | E5: Eklemli Bomlu Platform (Manlift) | F5: Вилочный Погрузчик | G5: HAULOTTE 41 RTJ PRO (НС732) | H5: 5766HX50 | I5: 41 м
A6: =SUBTOTAL(3,C$3:C6) -> 4 | B6: AO AVTOKRAN ARENDA | C6: SRU | E6: Forklift (Teleskopik) | F6: Телескопический Погрузчик | G6: MANITU | H6: 5017ХТ50 | I6: 6 тон
A7: =SUBTOTAL(3,C$3:C7) -> 5 | B7: OOO TOMAYLI | C7: SRU | E7: Tır (Çekici) | F7: Седельный Тягач | G7: КАМАЗ 65116-А4 | H7: У315СВ797 | I7: 20 тон | K7: УТ044677
A8: =SUBTOTAL(3,C$3:C8) -> 6 | B8: OOO ATLANT | C8: SRU | E8: Lowbet Çekici | F8: Трал Длинномер | G8: DAF XF | H8: Т601ЕА163 | I8: 49 тон | K8: ВУ807350
A9: =SUBTOTAL(3,C$3:C9) -> 7 | B9: IP SHMOYLOV | C9: SRU | E9: Damperli Kamyon | F9: Самосвал | G9: KAMAZ 6520-53 | H9: H554CC15 | I9: 33 тон
A10: =SUBTOTAL(3,C$3:C98) -> 82 | B10: IP MUSAYEV | C10: GARAJ-AMBAR | E10: Mobil Vinç | F10: Мобильный кран | G10: LIEBHERR LTM 1050 | H10: О814СО197 | I10: 50 тон
A11: =SUBTOTAL(3,C$3:C11) -> 9 | B11: OOO ARKADA-64 | C11: DCU | E11: Mobil Vinç | F11: Мобильный кран | G11: ZOOMLION ZАТ 3500V | H11: М 815 ТХ 28 | I11: 350 тон
A12: =SUBTOTAL(3,C$3:C12) -> 10 | B12: OOO ARKADA-64 | C12: DCU | E12: Mobil Vinç | F12: Мобильный кран | G12: XCMG XCA220_S | H12: X 448 BX 323 | I12: 220 тон (170 тон)
A13: =SUBTOTAL(3,C$3:C13) -> 11 | B13: OOO ARKADA-64 | C13: DCU | E13: Paletli Vinç | F13: Гусеничный кран | G13: XCMG XGC 150-IA | H13: 5724 УВ 23 | I13: 150 тн
A14: =SUBTOTAL(3,C$3:C14) -> 12 | B14: OOO ARKADA-64 | C14: DCU | E14: Mobil Vinç | F14: Мобильный кран | G14: LIEBHERR LTM 230 | H14: X 295 KM 193 | I14: 230 тон(160 тон)
A15: =SUBTOTAL(3,C$3:C15) -> 13 | B15: OOO ARKADA-64 | C15: DCU | E15: Mobil Vinç | F15: Мобильный кран | G15: PALFINQER SANY SRC 1200C | H15: 9659 ХХ 23 | I15: 120 тон
A16: =SUBTOTAL(3,C$3:C16) -> 14 | B16: OOO ARKADA-64 | C16: DCU | E16: Mobil Vinç | F16: Мобильный кран | G16: ZOOMLION ZTC800V | H16: Е 249 ВО 323 | I16: 80 тон
A17: =SUBTOTAL(3,C$3:C17) -> 15 | B17: KRANSPETSTSENTR | C17: DCU | E17: Mobil Vinç | F17: Мобильный кран | G17: DEMAG AC60 | H17: 1460 HX 77 | I17: 60 тон
A18: =SUBTOTAL(3,C$3:C18) -> 16 | B18: OOO GENEZIS | C18: DCU | E18: Mobil Vinç | F18: Мобильный кран | G18: XCMG XCT55-S/44 | H18: В 826 ХС 790 | I18: 55 тон
A19: =SUBTOTAL(3,C$3:C19) -> 17 | B19: OOO GENEZIS | C19: DCU | E19: Mobil Vinç | F19: Мобильный кран | G19: КС55721-1B | H19: Т 885 МК 790 | I19: 35 тон
A20: =SUBTOTAL(3,C$3:C20) -> 18 | B20: OOO GENEZIS | C20: DCU | E20: Mobil Vinç | F20: Мобильный кран | G20: SANY STC300T5 | H20: С 577 ТМ 790 | I20: 32 тон
A21: =SUBTOTAL(3,C$3:C21) -> 19 | B21: OOO ANTARES-RENT | C21: DCU | E21: Kule Vinç | F21: Башенный Кран | G21: ZTT 336B-12 | H21: 2025070189 (004 | I21: 12 тн
A22: =SUBTOTAL(3,C$3:C22) -> 20 | B22: OOO ANTARES-RENT | C22: DCU | E22: Kule Vinç | F22: Башенный Кран | G22: ZTT 336B-12 | H22: 2024030108 | I22: 12 тн
A23: =SUBTOTAL(3,C$3:C23) -> 21 | B23: OOO MIKRUSS | C23: DCU | E23: Hi-up | F23: Манипулятор | G23: ЗАМС 30404Е | H23: A 218 OP 155 | I23: 7/10 тн
A24: =SUBTOTAL(3,C$3:C24) -> 22 | B24: OOO MIKRUSS | C24: DCU | E24: Lowbet Çekici | F24: Трал Длинномер | G24: КАМАЗ5490 | H24: А 970 ХН 155 | I24: 18 м/40 т
A25: =SUBTOTAL(3,C$3:C25) -> 23 | B25: IP SMANALIEV AZAMAT KRIMOVICH | C25: DCU | E25: Tır (Çekici) | F25: Седельный Тягач | G25: КАМАЗ 5490 | H25: Е 220 ВА 250 | I25: 12 м/20 т
A26: =SUBTOTAL(3,C$3:C26) -> 24 | B26: IP SMANALIEV AZAMAT KRIMOVICH | C26: DCU | E26: Tır (Çekici) | F26: Седельный Тягач | G26: КАМАЗ5490 | H26: Т971 ВЕ 250 | I26: 12 м/20 т
A27: =SUBTOTAL(3,C$3:C27) -> 25 | B27: IP "SMANALIEV" | C27: DCU | E27: Tır (Çekici) | F27: Седельный Тягач | G27: КАМАЗ 5490-S5 | H27: X 051 TE 790 | I27: 12 м/20 т
A28: =SUBTOTAL(3,C$3:C28) -> 26 | B28: IP "SMANALIEV" | C28: DCU | E28: Tır (Çekici) | F28: Седельный Тягач | G28: КАМАЗ М1840 | H28: У 900 ВТ 550 | I28: 12 м/20 т
A29: =SUBTOTAL(3,C$3:C29) -> 27 | B29: OOO "ATLANT" | C29: DCU | E29: Tır (Çekici) | F29: Седельный Тягач | G29: КАМАЗ 65116-А4 | H29: О102АМ250 | I29: 12 м/20 т
A30: =SUBTOTAL(3,C$3:C30) -> 28 | B30: IP "CHERNOMURENKO" | C30: DCU | E30: Backhoe-Loader | F30: Экскаватор-Погрузчик | G30: JCB3CX | H30: 7535АВ 55 | I30: 3 тн
A31: =SUBTOTAL(3,C$3:C31) -> 29 | B31: OOO "NTT STROY" | C31: DCU | E31: Ekskavatör | F31: Экскаватор | G31: HITACHI ZX 330-5G | H31: 1423 РК 77
A32: =SUBTOTAL(3,C$3:C32) -> 30 | B32: IP "CHERNOMURENKO" | C32: DCU | E32: Mini Ekskavatör | F32: Мини-экскаватор | G32: JCB51R-1 T3 | H32: 6799 АВ 55
A33: =SUBTOTAL(3,C$3:C33) -> 31 | B33: IP "SMANALIEV" | C33: DCU | E33: Damperli Kamyon | F33: Самосвал | G33: КАМАЗ К5042 | H33: С 451 ЕВ 550 | I33: 25м3
A34: =SUBTOTAL(3,C$3:C34) -> 32 | B34: OOO "SPEKTR" | C34: DCU | E34: Eklemli Bomlu Platform (Manlift) | F34: Подъемник Коленчатый | G34: SINOBOOM AB 46 RT | H34: 4365 НА 50 | I34: 46/мт
A35: =SUBTOTAL(3,C$3:C35) -> 33 | B35: OOO "SPEKTR" | C35: DCU | E35: Eklemli Bomlu Platform (Manlift) | F35: Подъемник Коленчатый | G35: SINOBOOM AB 46 RJ | H35: 6609 НА 50 | I35: 46/мт
A36: =SUBTOTAL(3,C$3:C36) -> 34 | B36: OOO "SPEKTR" | C36: DCU | E36: Eklemli Bomlu Platform (Manlift) | F36: Подъемник Коленчатый | G36: DINGLI BA 44 RT | H36: 1169 НА 50 | I36: 44/мт
A37: =SUBTOTAL(3,C$3:C37) -> 35 | B37: OOO "SPEKTR" | C37: DCU | E37: Eklemli Bomlu Platform (Manlift) | F37: Подъемник Коленчатый | G37: DINGLI BA 44 RT | H37: 0738 НА 50 | I37: 44/мт
A38: =SUBTOTAL(3,C$3:C38) -> 36 | B38: OOO "SPEKTR" | C38: DCU | E38: Eklemli Bomlu Platform (Manlift) | F38: Подъемник Коленчатый | G38: DINGLI BA 44 RT | H38: 4530 НА 50 | I38: 44/мт
A39: =SUBTOTAL(3,C$3:C39) -> 37 | B39: OOO "SPEKTR" | C39: DCU | E39: Eklemli Bomlu Platform (Manlift) | F39: Подъемник Коленчатый | G39: DINGLI BA 36 RT | H39: 0731 НА 50 | I39: 36/мт
A40: =SUBTOTAL(3,C$3:C40) -> 38 | B40: OOO "SPEKTR" | C40: DCU | E40: Eklemli Bomlu Platform (Manlift) | F40: Подъемник Коленчатый | G40: SINOBOOM AB26RJ PLUS | H40: 0845 НА 50 | I40: 26/мт
...

Sheet Kiradan Çıkartılan Ekipmanlar
A1: № | B1: Фирма | C1: Площадка | D1: ID Номер | E1: Тип Транспортного Средства ТР | F1: Тип Транспортного Средства РУ | G1: Марка/Модел | H1: Гос Номер | I1: характеристики | J1: Дата Начала | K1: Дата Окончания | L1: Описание
B2: ООО "Мир машин" | C2: DCU | E2: Forklift (Teleskopik) | F2: Телескопический Погрузчик | G2: JCB 540-170 | H2: 77 МО 0938 | I2: 17/ Мт
B3: ООО "Мир машин" | C3: DCU | E3: Forklift (Teleskopik) | F3: Телескопический Погрузчик | G3: JCB 540-170 | H3: 77 МН 8797 | I3: 17/ Мт
B4: ООО "СПЕКТР" | C4: DCU | E4: Eklemli Bomlu Platform (Manlift) | F4: Подъемник Коленчатый | G4: Dingli BA 41 RT | H4: 4482 НА 50 | I4: 41/мт
B5: ООО "АВТОКРАН АРЕНДА" | C5: DCU | E5: Eklemli Bomlu Platform (Manlift) | F5: Подъемник Коленчатый | G5: HAULOTTE HA41 PX | H5: 4994 ХО 50 | I5: 41/мт
B6: ИП "Черномуренко" | C6: DCU | E6: Hi-up | F6: Манипулятор | G6: 78F10278F102 | H6: В 779 ОК 155 | I6: 7/10 тн
B7: ООО "Габарит" | C7: DCU | E7: Mobil Vinç | F7: Мобильный кран | G7: КС 65717 | H7: В 187 ХТ 763 | I7: 50 тн
B8: ООО "СПЕКТР" | C8: DCU | E8: Eklemli Bomlu Platform (Manlift) | F8: Подъемник Коленчатый | G8: Dingli BA 36 RT | H8: 0730 НА 50 | I8: 36/мт
B9: OOO MIR STROY KRAN | C9: SRU | E9: Mobil Vinç | F9: Мобильный кран | G9: LTM-1050-3.1 | H9: В179ТО799 | I9: 50 тон
B10: ООО "Габарит" | C10: DCU | E10: Mobil Vinç | F10: Мобильный кран | G10: SANY STС250Е5-5 | H10: X 382 KC 763 | I10: 25 тн
B11: ООО "АвтоСпецСтрой" | C11: DCU | E11: Mobil Vinç | F11: Мобильный кран | G11: XCMG XCT70-S | H11: О 381 НУ 193 | I11: 70 тн
B12: ЕНКИ | C12: SRU | E12: Kompressör | F12: Компрессор | G12: Chicago Pneumatic CPS350-12 | H12: - | I12: 12 бар
B13: AO AVTOKRAN ARENDA (ЗАО АВТОКРАН АРЕНДА) | C13: SRU | E13: Eklemli Bomlu Platform (Manlift) | F13: Телескопический Погрузчик | G13: HAULOTTE 32 RTJ PRO (HM936) | H13: 9051XM50 | I13: 32 м
... B16: ООО ГАБАРИТ | C16: DCU | E16: Mobil Vinç | F16: Мобильный кран | G16: XCMG XCT55_S | H16: Х 832 ОС 763 | I16: 50 тн
A17: 16 | B17: OOO GABARIT | C17: DCU | E17: Mobil Vinç | F17: Мобильный кран | G17: ZOOMLION ZTC600V | H17: В 555 УЕ 163 | I17: 60 тон

Sheet Satlan ve Hurdaya cikanlar
A1: № | B1: Фирма | C1: Площадка | D1: ID Номер | E1: Тип Транспортного Средства ТР | F1: Тип Транспортного Средства РУ | G1: Марка/Модел | H1: Гос Номер | I1: VIN № | J1: Характеристики | K1: Год Выпуска, г | L1: Вес ,Кг | M1: Габаритные Размеры (Д, Ш, В) | N1: Мощность Двигателя, кВт | O1: Марка Двигателя | P1: Номер Двигателя | Q1: Зарегистрированная фирма | R1: Дата Поступления | S1: Документы | T1: Дата снять | U1: Описание
A2: 1 | B2: URC | C2: Ofis | D2: MB-105 | E2: Minibüs | F2: Микроавтобус | G2: HYUJNDAI H-1 | H2: О 801 УК 799 | I2: XWEWH81KBM0001167 | J2: 3030 кг - 4х2 Дизель | K2: 2021 | L2: 2297 | M2: 5150х1920х1925 мм | N2: 125 кВт | O2: Kia Мotors D4CB-V-5 | P2: D4CBM208865 | Q2: USTAY | R2: - | S2: Ortak Klasor Linki verilecek | T2: 46256 | U2: Kaza sonrasi Sgorta sirketine gitti
A3: 2
A4: 3
A5: 4

Sheet Jeneratör Grubu
A1: № | B1: ID № | C1: Şantiye | D1: Makine Ekipman Tipi TR. | E1: Makine Ekipman Tipi RU. | F1: Marka/Model | G1: Plaka | H1: VIN № | I1: Teknik Özellikler | J1: Üretim yılı | K1: Ağırlık, kg | L1: Genel Boyutlar (U, G, Y) | M1: Motor gücü (кВт) | N1: Motor markası/modeli | O1: Motor Numarası | P1: Kayıtlı Şirket | Q1: Geliş Tarihi | R1: Belge / Doküman. | S1: Ana İş Grubu (Vida / Alternatör)
A2: № | B2: ID Номер | C2: Площадка | D2: Тип Транспортного Средства ТР | E2: Тип Транспортного Средства РУ | F2: Марка/Модел | G2: Гос Номер | H2: VIN № | I2: Характеристики | J2: Год Выпуска, г | K2: Вес ,Кг | L2: Габаритные Размеры (Д, Ш, В) | M2: Мощность Двигателя, кВт | N2: Марка Двигателя | O2: Номер Двигателя | P2: Зарегистрированная фирма | Q2: Дата Поступления | R2: Документы | S2: Главный узел (Винтовой блок / Альтернатор)
A3: 1 | B3: COM-101 | C3: SRU | D3: Kompressör | E3: Компрессор | F3: ZIF-ПВ 10/1,0 | G3: 1747 | H3: 1747 | I3: 10 бар | J3: - | K3: 1570 | L3: 2270х1250х1520мм | M3: 77–90 кВт | N3: ММЗ Д-245 | O3: - | P3: - | Q3: - | R3: Ortak Klasor Linki verilecek
A4: 2 | B4: COM-102 | C4: SRU | D4: Kompressör | E4: Компрессор | F4: ZIF-ПВ 10/1,0 | G4: 1685 | H4: 1685 | I4: 10 бар | J4: - | K4: 1570 | L4: 2270х1250х1520мм | M4: 77–90 кВт | N4: ММЗ Д-245 | O4: - | P4: - | Q4: - | R4: Ortak Klasor Linki verilecek
A5: 3 | B5: COM-103 | C5: DCU | D5: Kompressör | E5: Компрессор | F5: ZIF-ПВ 10/1,0 | G5: 1500 | H5: 1500 | I5: 10 бар | J5: 2020 | K5: 1570 | L5: 2270х1250х1520мм | M5: 77–90 кВт | N5: ММЗ Д-245 | O5: - | P5: - | Q5: - | R5: Ortak Klasor Linki verilecek
A6: 4 | B6: COM-104 | C6: DCU | D6: Kompressör | E6: Компрессор | F6: Remeza ДК-10/10 | G6: 201226 | H6: 201226 | I6: 10 бар | J6: - | K6: 1800 | L6: 3800х1750х2050 мм | M6: 77–90 кВт | N6: ММЗ Д-245 | O6: ММЗ AL4R2 2451003122-5 | P6: - | Q6: - | R6: Ortak Klasor Linki verilecek
A7: 6 | B7: COM-105 | C7: SRU | D7: Kompressör | E7: Компрессор | F7: ATLAS COPCO XAHS 400 PACE | G7: YA302475XLW542782 | H7: YA302475XLW542782 | I7: 12 бар | J7: - | K7: 1700 | L7: 3941х1716х2022 мм | M7: 93 кВт | N7: Cummins QSB3.9-C130-31 | O7: - | P7: - | Q7: - | R7: Ortak Klasor Linki verilecek
A8: 6 | B8: COM-106 | C8: DCU | D8: Kompressör | E8: Компрессор | F8: ATLAS COPCO XAHS 400 PACE | G8: YA3024755MW543663 | H8: YA3024755MW543663 | I8: 12 бар | J8: - | K8: 1700 | L8: 3941х1716х2022 мм | M8: 93 кВт | N8: Cummins QSB3.9-C130-31 | O8: - | P8: - | Q8: - | R8: Ortak Klasor Linki verilecek
A9: 7 | B9: COM-107 | C9: DCU | D9: Kompressör | E9: Компрессор | F9: ATLAS COPCO XAHS 400 PACE | G9: YA3024755XLW542782 | H9: YA3024755XLW542782 | I9: 12 бар | J9: - | K9: 1700 | L9: 3941х1716х2022 мм | M9: 93 кВт | N9: Cummins QSB3.9-C130-31 | O9: - | P9: - | Q9: - | R9: Ortak Klasor Linki verilecek
A10: 8 | B10: COM-108 | C10: DCU | D10: Kompressör | E10: Компрессор | F10: ATLAS COPCO XAS 88 KD | G10: YA3064705LW667200 | H10: YA3064705LW667200 | I10: 7 бар | J10: - | K10: 750 | L10: 2240х1345х1400 мм | M10: 33 кВт | N10: Kubota V1505T | O10: - | P10: - | Q10: - | R10: Ortak Klasor Linki verilecek
A11: 9 | B11: COM-109 | C11: DCU | D11: Kompressör | E11: Компрессор | F11: ATLAS COPCO XAS 88 KD | G11: YA3024704KW666338 | H11: YA3024704KW666338 | I11: 7 бар | J11: - | K11: 750 | L11: 2240х1345х1400 мм | M11: 33 кВт | N11: Kubota V1505T | O11: - | P11: - | Q11: - | R11: Ortak Klasor Linki verilecek
A12: 10 | B12: COM-110 | C12: SRU | D12: Kompressör | E12: Компрессор | F12: DALGAKIRAN W210 | G12: PS027153 | H12: PS027153 | I12: 12 бар | J12: - | K12: 680 | L12: 1640x1175x1100 мм | M12: 37 кВт | N12: 380 В (трехфазный) | O12: - | P12: - | Q12: - | R12: Ortak Klasor Linki verilecek
A13: 11 | B13: COM-111 | C13: DCU | D13: Kompressör | E13: Компрессор | F13: BAYSAR DS350-12D | G13: A15325-06/6 | H13: A15325-06/6 | I13: 12 бар | J13: - | K13: 1830 | L13: 2676х1456х1570 мм | M13: 93 кВт | N13: Cummins 4BTA3.9-C125 | O13: - | P13: - | Q13: - | R13: Ortak Klasor Linki verilecek
A14: 12 | B14: COM-112 | C14: DCU | D14: Kompressör | E14: Компрессор | F14: BERG VK-90 | G14: - | H14: - | I14: 12 бар | J14: - | K14: 1600 | L14: 2100х1400х1780 мм | M14: 90 кВт | N14: 380 В (трехфазный) | O14: - | P14: - | Q14: - | R14: Ortak Klasor Linki verilecek
A15: 14 | B15: COM-113 | C15: SRU | D15: Kompressör | E15: Компрессор | F15: ET SDN 550T-15 | G15: 260119006N | H15: 260119006N | I15: 12 бар | J15: 2026 | K15: 2500 | L15: 2805 x 1525 x 2182 мм. | M15: 132 кВт | N15: Cummins 6BTA5.9-C180-II | P15: - | Q15: - | R15: Ortak Klasor Linki verilecek
A16: 16 | B16: COM-114 | C16: SRU | D16: Kompressör | E16: Компрессор | F16: ET SDN 550T-15 | G16: 260119008N | H16: 260119008N | I16: 12 бар | J16: 2026 | K16: 2500 | L16: 2805 x 1525 x 2182 мм. | M16: 132 кВт | N16: Cummins 6BTA5.9-C180-II | P16: - | Q16: - | R16: Ortak Klasor Linki verilecek
A17: 16 | B17: COM-115 | C17: DCU | D17: Kompressör | E17: Компрессор | F17: ET SDN 550T-15 | G17: 260119010N | H17: 260119010N | I17: 12 бар | J17: 2026 | K17: 2500 | L17: 2805 x 1525 x 2182 мм. | M17: 132 кВт | N17: Cummins 6BTA5.9-C180-II | O17: 93593325 | P17: - | Q17: - | R17: Ortak Klasor Linki verilecek
A18: 16 | B18: COM-116 | C18: DCU | D18: Kompressör | E18: Компрессор | F18: ET SDN 390T-12CS | G18: 260520036N | H18: 260520036N | I18: 12 бар | J18: 2026 | K18: 1700 | L18: 2220x1870x1950 ММ. | M18: 93 кВт | N18: 4BTAA3,9-C125-II | O18: 93651786 | P18: - | Q18: - | R18: Ortak Klasor Linki verilecek
A19: 16 | B19: COM-117 | C19: DCU | D19: Kompressör | E19: Компрессор | F19: ET SDN 390T-12CS | G19: 260520038N | H19: 260520038N | I19: 12 бар | J19: 2026 | K19: 1700 | L19: 2220x1870x1950 ММ. | M19: 93 кВт | N19: 4BTAA3,9-C125-II | O19: 93653449 | P19: - | Q19: - | R19: Ortak Klasor Linki verilecek
A20: 16 | B20: IJ-101 | C20: SRU | D20: Işıldaklı Jeneratör | E20: Осветительная Мачта | F20: ATLAS COPCO HILIGHT V4 | G20: YA302988XKW922161 | H20: YA302988XKW922161 | I20: 4x1000 Вт | J20: - | K20: 694 | L20: 1670x1100x2500 мм | M20: 9.9 кВт | N20: Kubota Z482 | O20: - | P20: - | Q20: - | R20: Ortak Klasor Linki verilecek
A21: 17 | B21: IJ-102 | C21: SRU | D21: Işıldaklı Jeneratör | E21: Осветительная Мачта | F21: ATLAS COPCO HILIGHT V4 | G21: YA3029888KW922160 | H21: YA3029888KW922160 | I21: 4x1000 Вт | J21: - | K21: 694 | L21: 1670x1100x2500 мм | M21: 9.9 кВт | N21: Kubota Z482 | O21: - | P21: - | Q21: - | R21: Ortak Klasor Linki verilecek
A22: 18 | B22: IJ-103 | C22: SRU | D22: Işıldaklı Jeneratör | E22: Осветительная Мачта | F22: ATLAS COPCO HILIGHT V4 | G22: YA3029888KW922157 | H22: YA3029888KW922157 | I22: 4x1000 Вт | J22: - | K22: 694 | L22: 1670x1100x2500 мм | M22: 9.9 кВт | N22: Kubota Z482 | O22: - | P22: - | Q22: - | R22: Ortak Klasor Linki verilecek
A23: 19 | B23: IJ-104 | C23: SRU | D23: Işıldaklı Jeneratör | E23: Осветительная Мачта | F23: ATLAS COPCO HILIGHT V4 | G23: YA3029889LW925005 | H23: YA3029889LW925005 | I23: 4x1000 Вт | J23: - | K23: 694 | L23: 1670x1100x2500 мм | M23: 9.9 кВт | N23: Kubota Z482 | O23: - | P23: - | Q23: - | R23: Ortak Klasor Linki verilecek
A24: 20 | B24: IJ-105 | C24: SRU | D24: Işıldaklı Jeneratör | E24: Осветительная Мачта | F24: ATLAS COPCO HILIGHT V4 | G24: YA3029883KW920252 | H24: YA3029883KW920252 | I24: 4x1000 Вт | J24: - | K24: 694 | L24: 1670x1100x2500 мм | M24: 9.9 кВт | N24: Kubota Z482 | O24: - | P24: - | Q24: - | R24: Ortak Klasor Linki verilecek
A25: 21 | B25: IJ-106 | C25: SRU | D25: Işıldaklı Jeneratör | E25: Осветительная Мачта | F25: ATLAS COPCO HILIGHT V4 | G25: YA3029883KW920249 | H25: YA3029883KW920249 | I25: 4x1000 Вт | J25: - | K25: 694 | L25: 1670x1100x2500 мм | M25: 9.9 кВт | N25: Kubota Z482 | O25: - | P25: - | Q25: - | R25: Ortak Klasor Linki verilecek
A26: 22 | B26: IJ-107 | C26: DCU | D26: Işıldaklı Jeneratör | E26: Осветительная Мачта | F26: ATLAS COPCO HILIGHT V4 | G26: YA3029887MW927711 | H26: YA3029887MW927711 | I26: 4x1000 Вт | J26: - | K26: 694 | L26: 1670x1100x2500 мм | M26: 9.9 кВт | N26: Kubota Z482 | O26: - | P26: - | Q26: - | R26: Ortak Klasor Linki verilecek
A27: 23 | B27: IJ-108 | C27: DCU | D27: Işıldaklı Jeneratör | E27: Осветительная Мачта | F27: ATLAS COPCO HILIGHT V4 | G27: YA3029880LW925006 | H27: YA3029880LW925006 | I27: 4x1000 Вт | J27: - | K27: 694 | L27: 1670x1100x2500 мм | M27: 9.9 кВт | N27: Kubota Z482 | O27: - | P27: - | Q27: - | R27: Ortak Klasor Linki verilecek
A28: 24 | B28: IJ-109 | C28: DCU | D28: Işıldaklı Jeneratör | E28: Осветительная Мачта | F28: ATLAS COPCO HILIGHT V4 | G28: YA3029965MW927901 | H28: YA3029965MW927901 | I28: 4x1000 Вт | J28: - | K28: 694 | L28: 1670x1100x2500 мм | M28: 9.9 кВт | N28: Kubota Z482 | O28: - | P28: - | Q28: - | R28: Ortak Klasor Linki verilecek
A29: 25 | B29: IJ-110 | C29: DCU | D29: Işıldaklı Jeneratör | E29: Осветительная Мачта | F29: ATLAS COPCO HILIGHT V4 | G29: YA3029889KW920675 | H29: YA3029889KW920675 | I29: 4x1000 Вт | J29: - | K29: 694 | L29: 1670x1100x2500 мм | M29: 9.9 кВт | N29: Kubota Z482 | O29: - | P29: - | Q29: - | R29: Ortak Klasor Linki verilecek
A30: 26 | B30: IJ-111 | C30: DCU | D30: Işıldaklı Jeneratör | E30: Осветительная Мачта | F30: ATLAS COPCO HILIGHT V4 | G30: YA3029887KW922165 | H30: YA3029887KW922165 | I30: 4x1000 Вт | J30: - | K30: 694 | L30: 1670x1100x2500 мм | M30: 9.9 кВт | N30: Kubota Z482 | O30: - | P30: - | Q30: - | R30: Ortak Klasor Linki verilecek
A31: 27 | B31: IJ-112 | C31: SRU | D31: Işıldaklı Jeneratör | E31: Осветительная Мачта | F31: GENERAC VT8 | G31: 10004334 | H31: 10004334 | I31: 4x1000 Вт | J31: - | K31: 719 | L31: 2690х1300х2500 мм | M31: - | N31: - | O31: - | P31: - | Q31: - | R31: Ortak Klasor Linki verilecek
A32: 28 | B32: IJ-113 | C32: SRU | D32: Işıldaklı Jeneratör | E32: Осветительная Мачта | F32: GENERAC VT8 | G32: 10004329 | H32: 10004329 | I32: 4x1000 Вт | J32: - | K32: 719 | L32: 2690х1300х2500 мм | M32: - | N32: - | O32: - | P32: - | Q32: - | R32: Ortak Klasor Linki verilecek
A33: 29 | B33: IJ-114 | C33: SRU | D33: Işıldaklı Jeneratör | E33: Осветительная Мачта | F33: GENERAC VT8 | G33: 16000388 | H33: 16000388 | I33: 4x1000 Вт | J33: - | K33: 719 | L33: 2690х1300х2500 мм | M33: - | N33: - | O33: - | P33: - | Q33: - | R33: Ortak Klasor Linki verilecek
A34: 30 | B34: JD-101 | C34: DCU | D34: Jeneratör | E34: Дизельный Генератор | F34: HERTZ HG 275 DC | G34: - | H34: - | I34: 200 кВт | J34: 2021 | K34: 2685 | L34: 3940х1300х1850 мм | M34: 294 кВт | N34: Doosan P126TI-II | O34: Doosan P126TI-II | P34: EDI0C082203 | Q34: - | R34: Ortak Klasor Linki verilecek
A35: 31 | B35: JD-102 | C35: GARAJ-AMBAR | D35: Jeneratör | E35: Дизельный Генератор | F35: ISTOK A50C-1PM25 | G35: 1907643 | H35: 1907643 | I35: - | J35: - | K35: - | L35: - | M35: - | N35: - | O35: - | P35: - | Q35: - | R35: Ortak Klasor Linki verilecek
A36: 32 | B36: JD-103 | C36: GARAJ-AMBAR | D36: Jeneratör | E36: Дизельный Генератор | F36: MGE 100 T 400 TEKSAN | G36: - | H36: - | I36: 100 кВт | J36: - | K36: 1540 | L36: 2200х800х1270 мм | M36: 118 кВт | N36: Doosan D1146T | O36: EAD0E967564 | P36: - | Q36: - | R36: Ortak Klasor Linki verilecek | S36: G1R250SD

Sheet Toplam Ekipman
